INFO     log:logger.py:62 ------开始执行test_admin_login用例------
ERROR    log:logger.py:66 ------test_admin_login用例执行失败，失败原因：'name'------
ERROR    log:logger.py:67 test_admin_login 用例 is error,here are details:Traceback (most recent call last):
  File "D:\daima\xin-daima\two-pytest-api-automation2\common\logger.py", line 64, in log
    func(*args, **kwargs)
  File "D:\daima\xin-daima\two-pytest-api-automation2\case\test_receiving\test_add_address.py", line 32, in test_admin_login
    ,name=case_body['name']
KeyError: 'name'