[2021-11-17 09:44:43,219][logger.py 61][INFO]: ------开始执行dao_zhang用例------
[2021-11-17 09:44:43,220][logger.py 65][ERROR]: ------dao_zhang用例执行失败，失败原因：------
[2021-11-17 09:44:43,220][logger.py 66][ERROR]: dao_zhang 用例 is error,here are details:Traceback (most recent call last):
  File "D:/daima/xin-daima/two-pytest-api-automation/common/logger.py", line 63, in log
    func(*args, **kwargs)
  File "D:/daima/xin-daima/two-pytest-api-automation/common/logger.py", line 75, in dao_zhang
    assert 1==2
AssertionError

[2021-11-17 09:55:44,302][logger.py 61][INFO]: ------开始执行dao_zhang用例------
[2021-11-17 09:55:44,303][logger.py 65][ERROR]: ------dao_zhang用例执行失败，失败原因：------
[2021-11-17 09:55:44,303][logger.py 66][ERROR]: dao_zhang 用例 is error,here are details:Traceback (most recent call last):
  File "D:/daima/xin-daima/two-pytest-api-automation/common/logger.py", line 63, in log
    func(*args, **kwargs)
  File "D:/daima/xin-daima/two-pytest-api-automation/common/logger.py", line 75, in dao_zhang
    assert 1==2
AssertionError

[2021-11-17 09:55:51,601][logger.py 61][INFO]: ------开始执行dao_zhang用例------
[2021-11-17 09:55:51,602][logger.py 65][ERROR]: ------dao_zhang用例执行失败，失败原因：------
[2021-11-17 09:55:51,602][logger.py 66][ERROR]: dao_zhang 用例 is error,here are details:Traceback (most recent call last):
  File "D:/daima/xin-daima/two-pytest-api-automation/common/logger.py", line 63, in log
    func(*args, **kwargs)
  File "D:/daima/xin-daima/two-pytest-api-automation/common/logger.py", line 75, in dao_zhang
    assert 1==2
AssertionError

[2021-11-17 13:09:39,187][logger.py 61][INFO]: ------开始执行test_admin_login用例------
[2021-11-17 13:09:39,242][logger.py 61][INFO]: ------开始执行assert_api用例------
[2021-11-17 13:09:39,242][logger.py 69][INFO]: ------assert_api执行成功------
[2021-11-17 13:09:39,242][logger.py 69][INFO]: ------test_admin_login执行成功------
[2021-11-17 13:09:50,238][logger.py 61][INFO]: ------开始执行test_get_auth_code用例------
[2021-11-17 13:09:50,281][logger.py 61][INFO]: ------开始执行assert_api用例------
[2021-11-17 13:09:50,281][logger.py 69][INFO]: ------assert_api执行成功------
[2021-11-17 13:09:50,282][logger.py 69][INFO]: ------test_get_auth_code执行成功------
[2021-11-17 13:09:50,286][logger.py 61][INFO]: ------开始执行test_admin_login用例------
[2021-11-17 13:09:50,336][logger.py 61][INFO]: ------开始执行assert_api用例------
[2021-11-17 13:09:50,337][logger.py 69][INFO]: ------assert_api执行成功------
[2021-11-17 13:09:50,338][logger.py 69][INFO]: ------test_admin_login执行成功------
[2021-11-17 13:09:50,427][logger.py 61][INFO]: ------开始执行assert_api用例------
[2021-11-17 13:09:50,428][logger.py 69][INFO]: ------assert_api执行成功------
