INFO     log:logger.py:62 ------开始执行test_admin_login用例------
INFO     log:logger.py:62 ------开始执行assert_api用例------
INFO     log:assert_api.py:21 
assert:
 实际结果：{'code': 200, 'message': '操作成功', 'data': {'token': 'eyJhbGciOiJSUzI1NiIsInR5cCI6IkpXVCJ9.eyJ1c2VyX25hbWUiOiJhZG1pbiIsInNjb3BlIjpbImFsbCJdLCJpZCI6MjQzNDQyNywiZXhwIjoxNjQ4MTk0ODI2LCJhdXRob3JpdGllcyI6WyLliY3lj7DkvJrlkZgiXSwianRpIjoiMmM2YTI2MWMtZTQ3Ny00ODBlLTk2YjMtODU5ZmYyZmYyNTI2IiwiY2xpZW50X2lkIjoicG9ydGFsLWFwcCJ9.e8b_A1jSgcvQZo6ohS7decTBZe0km7dvcDD0ZwS2Lb8MM93iiNRPIiAFwGGo0Ekkv0YmOyVQ0bWpielIBvCNJS5HpHFR4rJ8Ln3mSpGX2MFJbcpoIZTByg27nzAJfkK9J57h_aPZkkMcx0raAPVhTnMl9zUzmI5wsb_3qofCTao', 'refreshToken': 'eyJhbGciOiJSUzI1NiIsInR5cCI6IkpXVCJ9.eyJ1c2VyX25hbWUiOiJhZG1pbiIsInNjb3BlIjpbImFsbCJdLCJhdGkiOiIyYzZhMjYxYy1lNDc3LTQ4MGUtOTZiMy04NTlmZjJmZjI1MjYiLCJpZCI6MjQzNDQyNywiZXhwIjoxNjQ4NzEzMjI2LCJhdXRob3JpdGllcyI6WyLliY3lj7DkvJrlkZgiXSwianRpIjoiZGM2MzExN2ItYTU4ZS00ZWE3LTk3OTUtNDZlNmYyMmVmMzFkIiwiY2xpZW50X2lkIjoicG9ydGFsLWFwcCJ9.USrEne9SY2oZkI_a5ez3qUmu4ZzAAYzMjQoAo1NB0yTLY4D-5CjUJOWSu5RhfoMdZWCR9cku4yhvjTcqVONtfLk3_ak7kWGBNhkxzNdGaFRLO4658_oUGLe7Ncqm0FRp4Ti6xHkwNj--7-S6R29H72vHGzF-fTuNPwLanIjNrUQ', 'tokenHead': 'Bearer ', 'expiresIn': 86399}}，
期望结果{'message': 'Bad credentials', 'code': 500}
ERROR    log:logger.py:66 ------assert_api用例执行失败，失败原因：------
ERROR    log:logger.py:67 assert_api 用例 is error,here are details:Traceback (most recent call last):
  File "D:\daima\xin-daima\two-pytest-api-automation2\common\logger.py", line 64, in log
    func(*args, **kwargs)
  File "D:\daima\xin-daima\two-pytest-api-automation2\common\assert_api.py", line 36, in assert_api
    raise e
  File "D:\daima\xin-daima\two-pytest-api-automation2\common\assert_api.py", line 27, in assert_api
    assert j == b[i]
AssertionError

ERROR    log:logger.py:66 ------test_admin_login用例执行失败，失败原因：------
ERROR    log:logger.py:67 test_admin_login 用例 is error,here are details:Traceback (most recent call last):
  File "D:\daima\xin-daima\two-pytest-api-automation2\common\logger.py", line 64, in log
    func(*args, **kwargs)
  File "D:\daima\xin-daima\two-pytest-api-automation2\case\test_member_controller\test_login.py", line 37, in test_admin_login
    assert_api(actual_data,case_data['expect'])
  File "D:\daima\xin-daima\two-pytest-api-automation2\common\logger.py", line 68, in log
    raise e
  File "D:\daima\xin-daima\two-pytest-api-automation2\common\logger.py", line 64, in log
    func(*args, **kwargs)
  File "D:\daima\xin-daima\two-pytest-api-automation2\common\assert_api.py", line 36, in assert_api
    raise e
  File "D:\daima\xin-daima\two-pytest-api-automation2\common\assert_api.py", line 27, in assert_api
    assert j == b[i]
AssertionError