INFO     log:logger.py:62 ------开始执行test_admin_login用例------
INFO     log:logger.py:62 ------开始执行assert_api用例------
INFO     log:assert_api.py:21 
assert:
 实际结果：{'code': 200, 'message': '操作成功', 'data': {'token': 'eyJhbGciOiJSUzI1NiIsInR5cCI6IkpXVCJ9.eyJ1c2VyX25hbWUiOiJhZG1pbiIsInNjb3BlIjpbImFsbCJdLCJpZCI6MjQzNDQyNywiZXhwIjoxNjQ4MTk0ODgxLCJhdXRob3JpdGllcyI6WyLliY3lj7DkvJrlkZgiXSwianRpIjoiY2ZlZWNiZGItNDQ5ZS00NjE1LWIzNmEtYTI5NTlmYTFlZmNlIiwiY2xpZW50X2lkIjoicG9ydGFsLWFwcCJ9.MrmDAg-YA-63vkLc91ba5JEnw3Yo4kELo6Y3oj9iEivzfHE_SvQg6Dm8wPqwnZYzPp3PPbM5qIFRQYpsgqnpV8usHI1Zlbz922JTk3HVfrjcaCrWScM113FCp7m4FHI17d-IHz8uHMW73NeQ7a_fsu4XH9ZFkYY58YjHyr1k8PE', 'refreshToken': 'eyJhbGciOiJSUzI1NiIsInR5cCI6IkpXVCJ9.eyJ1c2VyX25hbWUiOiJhZG1pbiIsInNjb3BlIjpbImFsbCJdLCJhdGkiOiJjZmVlY2JkYi00NDllLTQ2MTUtYjM2YS1hMjk1OWZhMWVmY2UiLCJpZCI6MjQzNDQyNywiZXhwIjoxNjQ4NzEzMjgxLCJhdXRob3JpdGllcyI6WyLliY3lj7DkvJrlkZgiXSwianRpIjoiYTkyODMzMTgtYTI2Zi00OWVhLTk5MmItNTE5M2U5ZDM3NTU3IiwiY2xpZW50X2lkIjoicG9ydGFsLWFwcCJ9.BcSGFYkZscMnKEEjwBkW3iSE-XTtcoUVIqWI8qyi93FWLW8FWbuIan85RgQK2WNx3oS5c-sV6Hs4Oky9NYIcyoH1n4rZg_rgxwd4NxE4nREE8m5IxVcAeRrmJpN60m0XcgBpfWAolEixLI1C-36tKQzzi-jZ7f3sBD9ZvFkEsFA', 'tokenHead': 'Bearer ', 'expiresIn': 86399}}，
期望结果{'message': 'Bad credentials', 'code': 500}
ERROR    log:logger.py:66 ------assert_api用例执行失败，失败原因：------
ERROR    log:logger.py:67 assert_api 用例 is error,here are details:Traceback (most recent call last):
  File "D:\daima\xin-daima\two-pytest-api-automation2\common\logger.py", line 64, in log
    func(*args, **kwargs)
  File "D:\daima\xin-daima\two-pytest-api-automation2\common\assert_api.py", line 36, in assert_api
    raise e
  File "D:\daima\xin-daima\two-pytest-api-automation2\common\assert_api.py", line 27, in assert_api
    assert j == b[i]
AssertionError

ERROR    log:logger.py:66 ------test_admin_login用例执行失败，失败原因：------
ERROR    log:logger.py:67 test_admin_login 用例 is error,here are details:Traceback (most recent call last):
  File "D:\daima\xin-daima\two-pytest-api-automation2\common\logger.py", line 64, in log
    func(*args, **kwargs)
  File "D:\daima\xin-daima\two-pytest-api-automation2\case\test_member_controller\test_login.py", line 37, in test_admin_login
    assert_api(actual_data,case_data['expect'])
  File "D:\daima\xin-daima\two-pytest-api-automation2\common\logger.py", line 68, in log
    raise e
  File "D:\daima\xin-daima\two-pytest-api-automation2\common\logger.py", line 64, in log
    func(*args, **kwargs)
  File "D:\daima\xin-daima\two-pytest-api-automation2\common\assert_api.py", line 36, in assert_api
    raise e
  File "D:\daima\xin-daima\two-pytest-api-automation2\common\assert_api.py", line 27, in assert_api
    assert j == b[i]
AssertionError