{"uuid": "2e264b11-bba4-4733-b9d9-953e8124fced", "children": ["e2191f5d-0225-4fb7-a3f2-4d5320f5e158", "d7ac9ade-84b3-43cb-933c-694545d843e6", "34a5b184-2a5d-484d-8c40-20b6949152ab"], "befores": [{"name": "ls_login", "status": "broken", "statusDetails": {"message": "TypeError: 'dict' object is not callable\n", "trace": "  File \"D:\\ruanjian\\python\\lib\\site-packages\\pluggy\\callers.py\", line 187, in _multicall\n    res = hook_impl.function(*args)\n  File \"D:\\ruanjian\\python\\lib\\site-packages\\_pytest\\fixtures.py\", line 1126, in pytest_fixture_setup\n    result = call_fixture_func(fixturefunc, request, kwargs)\n  File \"D:\\ruanjian\\python\\lib\\site-packages\\_pytest\\fixtures.py\", line 932, in call_fixture_func\n    fixture_result = fixturefunc(**kwargs)\n  File \"D:\\daima\\xin-daima\\two-pytest-api-automation\\case\\conftest.py\", line 50, in ls_login\n    login_ls(lisi_info,'lisi_token')\n  File \"D:\\daima\\xin-daima\\two-pytest-api-automation\\common\\logintoken.py\", line 83, in login_ls\n    return Login(admin_info,ls_token)\n  File \"D:\\daima\\xin-daima\\two-pytest-api-automation\\common\\logintoken.py\", line 45, in __init__\n    result = login(username=self.username, password=self.password)\n"}, "start": 1638258725104, "stop": 1638258725104}], "start": 1638258725104, "stop": 1638258725199}