{"uuid": "62035e46-677c-4afb-b522-39ec43190e91", "children": ["ebec4444-9da6-48d3-b65a-19484cae10e9", "94564f05-e8ab-4430-a173-8d663cbcef7a", "a46f7d0a-4c28-4c54-8081-0eef4a6b91a7"], "befores": [{"name": "als_login", "status": "broken", "statusDetails": {"message": "TypeError: 'dict' object is not callable\n", "trace": "  File \"D:\\ruanjian\\python\\lib\\site-packages\\pluggy\\callers.py\", line 187, in _multicall\n    res = hook_impl.function(*args)\n  File \"D:\\ruanjian\\python\\lib\\site-packages\\_pytest\\fixtures.py\", line 1126, in pytest_fixture_setup\n    result = call_fixture_func(fixturefunc, request, kwargs)\n  File \"D:\\ruanjian\\python\\lib\\site-packages\\_pytest\\fixtures.py\", line 932, in call_fixture_func\n    fixture_result = fixturefunc(**kwargs)\n  File \"D:\\daima\\xin-daima\\two-pytest-api-automation2\\conftest.py\", line 30, in als_login\n    login_ls(lisi_info,'lisi_token')\n  File \"D:\\daima\\xin-daima\\two-pytest-api-automation2\\common\\logintoken.py\", line 83, in login_ls\n    return Login(admin_info,ls_token)\n  File \"D:\\daima\\xin-daima\\two-pytest-api-automation2\\common\\logintoken.py\", line 46, in __init__\n    result = login(username=self.username, password=self.password)\n"}, "start": 1648177781618, "stop": 1648177781618}], "start": 1648177781618, "stop": 1648177781805}