INFO     log:logger.py:62 ------开始执行test_admin_login用例------
INFO     log:logger.py:62 ------开始执行assert_api用例------
INFO     log:assert_api.py:21 
assert:
 实际结果：{'code': 200, 'message': '操作成功', 'data': {'token': 'eyJhbGciOiJSUzI1NiIsInR5cCI6IkpXVCJ9.eyJ1c2VyX25hbWUiOiJhZG1pbiIsInNjb3BlIjpbImFsbCJdLCJpZCI6MjQzNDQyNywiZXhwIjoxNjQ4MTk0NDcyLCJhdXRob3JpdGllcyI6WyLliY3lj7DkvJrlkZgiXSwianRpIjoiZTdjYTY4NGEtNjYwMy00NTExLWJlYjktNmY4NzA2ZTM1OTU3IiwiY2xpZW50X2lkIjoicG9ydGFsLWFwcCJ9.ZlpT0SJtiVFKA0SulIo4ur6nGiZWLIOYUAp9P9nUuTz_KH8KhLJXiRFeAcFsdRdjCI1I6mHBEYEIbnNxdS17f6PK1jV_9kWFNI00dE0d-2XdTDpBRn2jKB31j9Xv-LBX1dwoik17SnIvBsfTbq4TdFdBu34at0R9eT0yuSKjv4s', 'refreshToken': 'eyJhbGciOiJSUzI1NiIsInR5cCI6IkpXVCJ9.eyJ1c2VyX25hbWUiOiJhZG1pbiIsInNjb3BlIjpbImFsbCJdLCJhdGkiOiJlN2NhNjg0YS02NjAzLTQ1MTEtYmViOS02Zjg3MDZlMzU5NTciLCJpZCI6MjQzNDQyNywiZXhwIjoxNjQ4NzEyODcyLCJhdXRob3JpdGllcyI6WyLliY3lj7DkvJrlkZgiXSwianRpIjoiMmRlYzg1YjItNzcwMy00NTQ3LWEzNjMtODRjODRjNTQ4M2M3IiwiY2xpZW50X2lkIjoicG9ydGFsLWFwcCJ9.gAc8SKdqA6G6sMhs4lC8p-vK_jRcJJLAJQTSACncdDWdF8FVGnVezgZT-Ck8txbfSbPc0ouuF1QkWuZPrZq2GJMvnoqzPJsGhKNHp7_LveEAE4GRiTkMDDUlt0it3LEv2JCM7JyPbh-mta0D_UOUoV4JJw7wK1NjmZmqjXWTLWU', 'tokenHead': 'Bearer ', 'expiresIn': 86399}}，
期望结果{'message': 'Bad credentials', 'code': 500}
ERROR    log:logger.py:66 ------assert_api用例执行失败，失败原因：------
ERROR    log:logger.py:67 assert_api 用例 is error,here are details:Traceback (most recent call last):
  File "D:\daima\xin-daima\two-pytest-api-automation2\common\logger.py", line 64, in log
    func(*args, **kwargs)
  File "D:\daima\xin-daima\two-pytest-api-automation2\common\assert_api.py", line 36, in assert_api
    raise e
  File "D:\daima\xin-daima\two-pytest-api-automation2\common\assert_api.py", line 27, in assert_api
    assert j == b[i]
AssertionError

ERROR    log:logger.py:66 ------test_admin_login用例执行失败，失败原因：------
ERROR    log:logger.py:67 test_admin_login 用例 is error,here are details:Traceback (most recent call last):
  File "D:\daima\xin-daima\two-pytest-api-automation2\common\logger.py", line 64, in log
    func(*args, **kwargs)
  File "D:\daima\xin-daima\two-pytest-api-automation2\case\test_member_controller\test_login.py", line 37, in test_admin_login
    assert_api(actual_data,case_data['expect'])
  File "D:\daima\xin-daima\two-pytest-api-automation2\common\logger.py", line 68, in log
    raise e
  File "D:\daima\xin-daima\two-pytest-api-automation2\common\logger.py", line 64, in log
    func(*args, **kwargs)
  File "D:\daima\xin-daima\two-pytest-api-automation2\common\assert_api.py", line 36, in assert_api
    raise e
  File "D:\daima\xin-daima\two-pytest-api-automation2\common\assert_api.py", line 27, in assert_api
    assert j == b[i]
AssertionError