INFO     log:logger.py:62 ------开始执行test_admin_login用例------
INFO     log:logger.py:62 ------开始执行assert_api用例------
INFO     log:assert_api.py:21 
assert:
 实际结果：{'code': 200, 'message': '操作成功', 'data': {'token': 'eyJhbGciOiJSUzI1NiIsInR5cCI6IkpXVCJ9.eyJ1c2VyX25hbWUiOiJhZG1pbiIsInNjb3BlIjpbImFsbCJdLCJpZCI6MjQzNDQyNywiZXhwIjoxNjQ4MTk0OTAyLCJhdXRob3JpdGllcyI6WyLliY3lj7DkvJrlkZgiXSwianRpIjoiYjEyZTEwZDUtNDI1YS00YzdmLTk1MWMtYjY1YmRhN2EwZTUyIiwiY2xpZW50X2lkIjoicG9ydGFsLWFwcCJ9.M8cIz-ll3ZSiHnrYI83weOz5kOV9GtmSwQE_f6f4D5-q0fj_iacru8S-4Y687DBLiIMUBn_CHma2boRAtEuBImx_DQ0gumI7ZFPPmXr28SVvZhHkpd7WMoCROmuKLuaXD_uId7n5MIY7x285dqn5ixfCZuLJyNCsNKlv-eCqedo', 'refreshToken': 'eyJhbGciOiJSUzI1NiIsInR5cCI6IkpXVCJ9.eyJ1c2VyX25hbWUiOiJhZG1pbiIsInNjb3BlIjpbImFsbCJdLCJhdGkiOiJiMTJlMTBkNS00MjVhLTRjN2YtOTUxYy1iNjViZGE3YTBlNTIiLCJpZCI6MjQzNDQyNywiZXhwIjoxNjQ4NzEzMzAyLCJhdXRob3JpdGllcyI6WyLliY3lj7DkvJrlkZgiXSwianRpIjoiYmIyNTlhZmYtY2Y4Ny00NDYzLWE1NGItNzRiOTU3MWNlMWJiIiwiY2xpZW50X2lkIjoicG9ydGFsLWFwcCJ9.BZxkyVhBC2E_g1LSqKlD-82ylwGCGdodEIxZEdxLf__AhJ3WJ4VHW_8ES4DlTiUFO2HGhksU9e_NA1plSixjznwRQjRbjInj9_kyCpSTxilVh5t-GyKTQsU0LP34Y9ZuUgVzkBbDXqgU9P93ivIHFfIPectrOFod3b2oK6-R-ng', 'tokenHead': 'Bearer ', 'expiresIn': 86399}}，
期望结果{'message': 'Bad credentials', 'code': 500}
ERROR    log:logger.py:66 ------assert_api用例执行失败，失败原因：------
ERROR    log:logger.py:67 assert_api 用例 is error,here are details:Traceback (most recent call last):
  File "D:\daima\xin-daima\two-pytest-api-automation2\common\logger.py", line 64, in log
    func(*args, **kwargs)
  File "D:\daima\xin-daima\two-pytest-api-automation2\common\assert_api.py", line 36, in assert_api
    raise e
  File "D:\daima\xin-daima\two-pytest-api-automation2\common\assert_api.py", line 27, in assert_api
    assert j == b[i]
AssertionError

ERROR    log:logger.py:66 ------test_admin_login用例执行失败，失败原因：------
ERROR    log:logger.py:67 test_admin_login 用例 is error,here are details:Traceback (most recent call last):
  File "D:\daima\xin-daima\two-pytest-api-automation2\common\logger.py", line 64, in log
    func(*args, **kwargs)
  File "D:\daima\xin-daima\two-pytest-api-automation2\case\test_member_controller\test_login.py", line 37, in test_admin_login
    assert_api(actual_data,case_data['expect'])
  File "D:\daima\xin-daima\two-pytest-api-automation2\common\logger.py", line 68, in log
    raise e
  File "D:\daima\xin-daima\two-pytest-api-automation2\common\logger.py", line 64, in log
    func(*args, **kwargs)
  File "D:\daima\xin-daima\two-pytest-api-automation2\common\assert_api.py", line 36, in assert_api
    raise e
  File "D:\daima\xin-daima\two-pytest-api-automation2\common\assert_api.py", line 27, in assert_api
    assert j == b[i]
AssertionError