INFO     log:logger.py:62 ------开始执行test_admin_login用例------
INFO     log:logger.py:62 ------开始执行assert_api用例------
INFO     log:assert_api.py:21 
assert:
 实际结果：{'code': 200, 'message': '操作成功', 'data': {'token': 'eyJhbGciOiJSUzI1NiIsInR5cCI6IkpXVCJ9.eyJ1c2VyX25hbWUiOiJhZG1pbiIsInNjb3BlIjpbImFsbCJdLCJpZCI6MjQzNDQyNywiZXhwIjoxNjQ4MTk3NzkwLCJhdXRob3JpdGllcyI6WyLliY3lj7DkvJrlkZgiXSwianRpIjoiODE1NGE3MjctMWI2Zi00NjkxLWIyYjctZDcyMTFjMjczNmQzIiwiY2xpZW50X2lkIjoicG9ydGFsLWFwcCJ9.YFFimEu9vwCkKO4OY1IOZDDSwok2tGSXUgGIOgYIRZmi_vxVST1pVI08_-XwBrlxRpmECQtYXJDjNSs2N-CXtuBauGi-o_H2JmKbUZ_vmyj9roJ1HyUpS-MQVmWgcqfxcG_ZE0Eu1QwQGNN6ZbCRqRaHXbTk0Pywd25N0U_6Lqo', 'refreshToken': 'eyJhbGciOiJSUzI1NiIsInR5cCI6IkpXVCJ9.eyJ1c2VyX25hbWUiOiJhZG1pbiIsInNjb3BlIjpbImFsbCJdLCJhdGkiOiI4MTU0YTcyNy0xYjZmLTQ2OTEtYjJiNy1kNzIxMWMyNzM2ZDMiLCJpZCI6MjQzNDQyNywiZXhwIjoxNjQ4NzE2MTkwLCJhdXRob3JpdGllcyI6WyLliY3lj7DkvJrlkZgiXSwianRpIjoiNzYxNWQ0ZDYtMTYwYy00MzUyLTgyOGYtZWVmNmFlODU4NWEwIiwiY2xpZW50X2lkIjoicG9ydGFsLWFwcCJ9.nobsfjl3cBHGLNvAM6m0PDAqBebkSudF4GnizwI191jQo4zGULbF9GYz0Kjo4LM4k0Dw0tUwrMKgPnnTrOU5k52hmZeU6x-DLCtrUVG8iSDghafiZ3K_TiAo9BcMzrR55lfatrIMAlL2BYlD4wtOVnc_pRZk33u1-xTuIAKaw6s', 'tokenHead': 'Bearer ', 'expiresIn': 86399}}，
期望结果{'message': 'Bad credentials', 'code': 500}
ERROR    log:logger.py:66 ------assert_api用例执行失败，失败原因：------
ERROR    log:logger.py:67 assert_api 用例 is error,here are details:Traceback (most recent call last):
  File "D:\daima\xin-daima\two-pytest-api-automation2\common\logger.py", line 64, in log
    func(*args, **kwargs)
  File "D:\daima\xin-daima\two-pytest-api-automation2\common\assert_api.py", line 36, in assert_api
    raise e
  File "D:\daima\xin-daima\two-pytest-api-automation2\common\assert_api.py", line 27, in assert_api
    assert j == b[i]
AssertionError

ERROR    log:logger.py:66 ------test_admin_login用例执行失败，失败原因：------
ERROR    log:logger.py:67 test_admin_login 用例 is error,here are details:Traceback (most recent call last):
  File "D:\daima\xin-daima\two-pytest-api-automation2\common\logger.py", line 64, in log
    func(*args, **kwargs)
  File "D:\daima\xin-daima\two-pytest-api-automation2\case\test_member_controller\test_login.py", line 37, in test_admin_login
    assert_api(actual_data,case_data['expect'])
  File "D:\daima\xin-daima\two-pytest-api-automation2\common\logger.py", line 68, in log
    raise e
  File "D:\daima\xin-daima\two-pytest-api-automation2\common\logger.py", line 64, in log
    func(*args, **kwargs)
  File "D:\daima\xin-daima\two-pytest-api-automation2\common\assert_api.py", line 36, in assert_api
    raise e
  File "D:\daima\xin-daima\two-pytest-api-automation2\common\assert_api.py", line 27, in assert_api
    assert j == b[i]
AssertionError