INFO     log:logger.py:62 ------开始执行test_get_auth_code用例------
ERROR    log:logger.py:66 ------test_get_auth_code用例执行失败，失败原因：'telephone'------
ERROR    log:logger.py:67 test_get_auth_code 用例 is error,here are details:Traceback (most recent call last):
  File "D:\daima\xin-daima\two-pytest-api-automation2\common\logger.py", line 64, in log
    func(*args, **kwargs)
  File "D:\daima\xin-daima\two-pytest-api-automation2\case\test_member_controller\test_auth_code.py", line 26, in test_get_auth_code
    actual_data = member_controller_z.get_auth_code(telephone = case_body['telephone'])
KeyError: 'telephone'