INFO     log:logger.py:62 ------开始执行test_admin_login用例------
INFO     log:logger.py:62 ------开始执行assert_api用例------
INFO     log:assert_api.py:21 
assert:
 实际结果：{'code': 200, 'message': '操作成功', 'data': {'token': 'eyJhbGciOiJSUzI1NiIsInR5cCI6IkpXVCJ9.eyJ1c2VyX25hbWUiOiJhZG1pbiIsInNjb3BlIjpbImFsbCJdLCJpZCI6MjQzNDQyNywiZXhwIjoxNjQ4MTk3NjQ3LCJhdXRob3JpdGllcyI6WyLliY3lj7DkvJrlkZgiXSwianRpIjoiYmEyZjFmNzktYWE2Ny00NTRkLTkwMGEtZDhkN2U2ZTA1NTc0IiwiY2xpZW50X2lkIjoicG9ydGFsLWFwcCJ9.U2UVZyJvObWA8aP0TqCAucpPP-Fh9zQQ4PCLjdCuLmI3Q-EqEWtRWU6rgjvG3URPTAordGWJWPgX4R4ecb4tHgh5gUofNISPrprtzCDZ_sN-5GNyO5S6cAFWS39Be_g0Wc3MumDk990hP13NWYHQgzw7O3kJ8VKR_w95nE9xews', 'refreshToken': 'eyJhbGciOiJSUzI1NiIsInR5cCI6IkpXVCJ9.eyJ1c2VyX25hbWUiOiJhZG1pbiIsInNjb3BlIjpbImFsbCJdLCJhdGkiOiJiYTJmMWY3OS1hYTY3LTQ1NGQtOTAwYS1kOGQ3ZTZlMDU1NzQiLCJpZCI6MjQzNDQyNywiZXhwIjoxNjQ4NzE2MDQ3LCJhdXRob3JpdGllcyI6WyLliY3lj7DkvJrlkZgiXSwianRpIjoiMjM0ZjNjMjUtZWZjNC00YzhlLWE3YWYtMzRiYjhmMzNhODdmIiwiY2xpZW50X2lkIjoicG9ydGFsLWFwcCJ9.ZmqcJ2jv4tU08hfQC0n_OgNQzvsxzZYrjN6BPH_vcn-oqUsBUCqXlmGYNfRHzWt7-62bwnlg2GzLx7fd7zoRDvkkMNmUONyHk3rE8oEbMCdMqw7xm1L14JPCieH3eaMaR8tmOfI_Xud0fQB0qI8eX_6egsrFAwLR_g5Rcopg-rU', 'tokenHead': 'Bearer ', 'expiresIn': 86399}}，
期望结果{'message': 'Bad credentials', 'code': 500}
ERROR    log:logger.py:66 ------assert_api用例执行失败，失败原因：------
ERROR    log:logger.py:67 assert_api 用例 is error,here are details:Traceback (most recent call last):
  File "D:\daima\xin-daima\two-pytest-api-automation2\common\logger.py", line 64, in log
    func(*args, **kwargs)
  File "D:\daima\xin-daima\two-pytest-api-automation2\common\assert_api.py", line 36, in assert_api
    raise e
  File "D:\daima\xin-daima\two-pytest-api-automation2\common\assert_api.py", line 27, in assert_api
    assert j == b[i]
AssertionError

ERROR    log:logger.py:66 ------test_admin_login用例执行失败，失败原因：------
ERROR    log:logger.py:67 test_admin_login 用例 is error,here are details:Traceback (most recent call last):
  File "D:\daima\xin-daima\two-pytest-api-automation2\common\logger.py", line 64, in log
    func(*args, **kwargs)
  File "D:\daima\xin-daima\two-pytest-api-automation2\case\test_member_controller\test_login.py", line 37, in test_admin_login
    assert_api(actual_data,case_data['expect'])
  File "D:\daima\xin-daima\two-pytest-api-automation2\common\logger.py", line 68, in log
    raise e
  File "D:\daima\xin-daima\two-pytest-api-automation2\common\logger.py", line 64, in log
    func(*args, **kwargs)
  File "D:\daima\xin-daima\two-pytest-api-automation2\common\assert_api.py", line 36, in assert_api
    raise e
  File "D:\daima\xin-daima\two-pytest-api-automation2\common\assert_api.py", line 27, in assert_api
    assert j == b[i]
AssertionError