INFO     log:logger.py:62 ------开始执行test_admin_login用例------
INFO     log:logger.py:62 ------开始执行assert_api用例------
INFO     log:assert_api.py:21 
assert:
 实际结果：{'code': 200, 'message': '操作成功', 'data': {'token': 'eyJhbGciOiJSUzI1NiIsInR5cCI6IkpXVCJ9.eyJ1c2VyX25hbWUiOiJhZG1pbiIsInNjb3BlIjpbImFsbCJdLCJpZCI6MjQzNDQyNywiZXhwIjoxNjQ4MTk1ODczLCJhdXRob3JpdGllcyI6WyLliY3lj7DkvJrlkZgiXSwianRpIjoiZTZjNjRiNmYtYjYyMC00ZDU5LThjMDYtNGZhODZlNjU1Y2Y0IiwiY2xpZW50X2lkIjoicG9ydGFsLWFwcCJ9.PJuuJypniRW7quNoqXbHAskTpl_l8487uukBnHyP6Uu7xwpTTRd4fpeNTxBk11qYVed1q5hAzIG5eHoNdyW5ksFJWa1AINizpevgglZiB0XNFUoX1SsbwjTXY3ecIfx0vl13_IHCmnb3BT6Tfv9RIJECkJ5KuvndtudGCBroPFs', 'refreshToken': 'eyJhbGciOiJSUzI1NiIsInR5cCI6IkpXVCJ9.eyJ1c2VyX25hbWUiOiJhZG1pbiIsInNjb3BlIjpbImFsbCJdLCJhdGkiOiJlNmM2NGI2Zi1iNjIwLTRkNTktOGMwNi00ZmE4NmU2NTVjZjQiLCJpZCI6MjQzNDQyNywiZXhwIjoxNjQ4NzE0MjczLCJhdXRob3JpdGllcyI6WyLliY3lj7DkvJrlkZgiXSwianRpIjoiOTg4NzNjZGYtMzIyYi00OGRlLTkxYTktOTEwZjdiMDEyZDgyIiwiY2xpZW50X2lkIjoicG9ydGFsLWFwcCJ9.CKkx-AyuF7M8fEBhnUGWL8dKb21A9Lt5y7NyOUkTIw8vU94chs7okQ1xteC70PdWU1pTKySLmdE-Nf6HFdzmruU56YZkhuUqiRsDGs75u9HtDgy6LqQOTYIS7a21X4BNXSPAnKI6uAneyAe5Bg_6ouDYzDe6lqi_4nb_IvpFOXU', 'tokenHead': 'Bearer ', 'expiresIn': 86399}}，
期望结果{'message': 'Bad credentials', 'code': 500}
ERROR    log:logger.py:66 ------assert_api用例执行失败，失败原因：------
ERROR    log:logger.py:67 assert_api 用例 is error,here are details:Traceback (most recent call last):
  File "D:\daima\xin-daima\two-pytest-api-automation2\common\logger.py", line 64, in log
    func(*args, **kwargs)
  File "D:\daima\xin-daima\two-pytest-api-automation2\common\assert_api.py", line 36, in assert_api
    raise e
  File "D:\daima\xin-daima\two-pytest-api-automation2\common\assert_api.py", line 27, in assert_api
    assert j == b[i]
AssertionError

ERROR    log:logger.py:66 ------test_admin_login用例执行失败，失败原因：------
ERROR    log:logger.py:67 test_admin_login 用例 is error,here are details:Traceback (most recent call last):
  File "D:\daima\xin-daima\two-pytest-api-automation2\common\logger.py", line 64, in log
    func(*args, **kwargs)
  File "D:\daima\xin-daima\two-pytest-api-automation2\case\test_member_controller\test_login.py", line 38, in test_admin_login
    assert_api(actual_data,case_data['expect'])
  File "D:\daima\xin-daima\two-pytest-api-automation2\common\logger.py", line 68, in log
    raise e
  File "D:\daima\xin-daima\two-pytest-api-automation2\common\logger.py", line 64, in log
    func(*args, **kwargs)
  File "D:\daima\xin-daima\two-pytest-api-automation2\common\assert_api.py", line 36, in assert_api
    raise e
  File "D:\daima\xin-daima\two-pytest-api-automation2\common\assert_api.py", line 27, in assert_api
    assert j == b[i]
AssertionError