INFO     log:logger.py:62 ------开始执行test_admin_login用例------
INFO     log:logger.py:62 ------开始执行assert_api用例------
INFO     log:assert_api.py:21 
assert:
 实际结果：{'code': 200, 'message': '操作成功', 'data': {'token': 'eyJhbGciOiJSUzI1NiIsInR5cCI6IkpXVCJ9.eyJ1c2VyX25hbWUiOiJhZG1pbiIsInNjb3BlIjpbImFsbCJdLCJpZCI6MjQzNDQyNywiZXhwIjoxNjQ4MTk3OTc0LCJhdXRob3JpdGllcyI6WyLliY3lj7DkvJrlkZgiXSwianRpIjoiZTQxYjg2ZWMtYTA0MC00Njg1LTg5ZTYtYzA3MjVlNDZlZjBhIiwiY2xpZW50X2lkIjoicG9ydGFsLWFwcCJ9.TaMb7-gZk6hOoQu-r_u4hlaum68vBHN9CSvufj2gYrBbMNkMXozJOmd4m7yYvFvZuOP1k8Pl6x-xIwI0LnQkkAOTFIfB_icTfy4XgceWe7rxDi3dNIh26n2EIB03XSBIwP6ZmCwbeFqhuZl4E4aO76LvcxPgraKoeYZ61oR2-So', 'refreshToken': 'eyJhbGciOiJSUzI1NiIsInR5cCI6IkpXVCJ9.eyJ1c2VyX25hbWUiOiJhZG1pbiIsInNjb3BlIjpbImFsbCJdLCJhdGkiOiJlNDFiODZlYy1hMDQwLTQ2ODUtODllNi1jMDcyNWU0NmVmMGEiLCJpZCI6MjQzNDQyNywiZXhwIjoxNjQ4NzE2Mzc0LCJhdXRob3JpdGllcyI6WyLliY3lj7DkvJrlkZgiXSwianRpIjoiOTQxMTY3OTUtYjVkYy00ZGQ0LWExMGMtNTdhYjg4NzNiM2RhIiwiY2xpZW50X2lkIjoicG9ydGFsLWFwcCJ9.MjlAV2kwhyZNKt86TzqwkvQT_SOJlZnWHAOdyAJ_3a5w_0b1puDpz9WGMZQZ0K8j6nDdj5v3W-rm_JjVNbDdPCX0HlK4cLdgFhKTtX4iG4WPdO5Pz5OoIQUNv_IC15AujYszPHYopoHzWyluKABRxl0C9bawiIYbDEYnL-ETGTw', 'tokenHead': 'Bearer ', 'expiresIn': 86399}}，
期望结果{'message': 'Bad credentials', 'code': 500}
ERROR    log:logger.py:66 ------assert_api用例执行失败，失败原因：------
ERROR    log:logger.py:67 assert_api 用例 is error,here are details:Traceback (most recent call last):
  File "D:\daima\xin-daima\two-pytest-api-automation2\common\logger.py", line 64, in log
    func(*args, **kwargs)
  File "D:\daima\xin-daima\two-pytest-api-automation2\common\assert_api.py", line 36, in assert_api
    raise e
  File "D:\daima\xin-daima\two-pytest-api-automation2\common\assert_api.py", line 27, in assert_api
    assert j == b[i]
AssertionError

ERROR    log:logger.py:66 ------test_admin_login用例执行失败，失败原因：------
ERROR    log:logger.py:67 test_admin_login 用例 is error,here are details:Traceback (most recent call last):
  File "D:\daima\xin-daima\two-pytest-api-automation2\common\logger.py", line 64, in log
    func(*args, **kwargs)
  File "D:\daima\xin-daima\two-pytest-api-automation2\case\test_member_controller\test_login.py", line 37, in test_admin_login
    assert_api(actual_data,case_data['expect'])
  File "D:\daima\xin-daima\two-pytest-api-automation2\common\logger.py", line 68, in log
    raise e
  File "D:\daima\xin-daima\two-pytest-api-automation2\common\logger.py", line 64, in log
    func(*args, **kwargs)
  File "D:\daima\xin-daima\two-pytest-api-automation2\common\assert_api.py", line 36, in assert_api
    raise e
  File "D:\daima\xin-daima\two-pytest-api-automation2\common\assert_api.py", line 27, in assert_api
    assert j == b[i]
AssertionError