{"uuid": "8e634601-5101-4289-b787-4c6da2cf1b4b", "children": ["17b32626-bdb6-4df3-b5a4-a835e1fc3f4d", "acc4e19b-1cc6-49b5-8be1-7a157ac65498", "3f4489fd-e058-42dd-94b9-c0926aaef6ba"], "befores": [{"name": "als_login", "status": "broken", "statusDetails": {"message": "TypeError: 'dict' object is not callable\n", "trace": "  File \"D:\\ruanjian\\python\\lib\\site-packages\\pluggy\\callers.py\", line 187, in _multicall\n    res = hook_impl.function(*args)\n  File \"D:\\ruanjian\\python\\lib\\site-packages\\_pytest\\fixtures.py\", line 1126, in pytest_fixture_setup\n    result = call_fixture_func(fixturefunc, request, kwargs)\n  File \"D:\\ruanjian\\python\\lib\\site-packages\\_pytest\\fixtures.py\", line 932, in call_fixture_func\n    fixture_result = fixturefunc(**kwargs)\n  File \"D:\\daima\\xin-daima\\two-pytest-api-automation2\\conftest.py\", line 30, in als_login\n    login_ls(lisi_info,'lisi_token')\n  File \"D:\\daima\\xin-daima\\two-pytest-api-automation2\\common\\logintoken.py\", line 83, in login_ls\n    return Login(admin_info,ls_token)\n  File \"D:\\daima\\xin-daima\\two-pytest-api-automation2\\common\\logintoken.py\", line 46, in __init__\n    result = login(username=self.username, password=self.password)\n"}, "start": 1648177891630, "stop": 1648177891630}], "start": 1648177891630, "stop": 1648177891729}